Workbook
Name ProjectRoot: 'Control Checks'!$XFD$1
Name Slicer_confidence_tier: #N/A
Name Slicer_confidence_tier1: #N/A
Name Slicer_match_status: #N/A

Sheet Transaction Detail
A1: bank_transaction_id | B1: ledger_id | C1: bank_date | D1: ledger_date | E1: bank_amount | F1: ledger_amount | G1: amount_difference | H1: date_difference_days | I1: bank_description | J1: ledger_description | K1: match_status | L1: match_reason | M1: confidence_score | N1: confidence_tier | O1: duplicate_flag | P1: duplicate_note
A2: 6e80ee9f-49b5-434f-8ab6-f192a2296e6c | B2: LED100001 | C2: 45104 | D2: 45104 | E2: 100 | F2: 100 | G2: 0 | H2: 0 | I2: GAS FILLING STATION | J2: GAS FILLING STATION | K2: Matched | L2: Exact amount + date + transaction type | M2: 95 | N2: High | O2: No | P2: No duplicate candidate
A3: a734aa85-4bf8-44c0-b508-305f554dc51e | B3: LED100002 | C3: 45105 | D3: 45105 | E3: 170 | F3: 170 | G3: 0 | H3: 0 | I3: GAS FILLING STATION | J3: GAS FILLING STATION | K3: Matched | L3: Exact amount + date + transaction type | M3: 95 | N3: High | O3: No | P3: No duplicate candidate
A4: dc44e071-399f-4ec2-b6ec-64f9e8a05a8a | B4: LED100003 | C4: 45133 | D4: 45133 | E4: 500 | F4: 500 | G4: 0 | H4: 0 | I4: GAS FILLING STATION | J4: GAS FILLING STATION | K4: Matched | L4: Exact amount + date + transaction type | M4: 95 | N4: High | O4: No | P4: No duplicate candidate
A5: 0adc1ed0-4809-462d-855c-84cda5593c80 | B5: LED100004 | C5: 45138 | D5: 45138 | E5: 15 | F5: 15 | G5: 0 | H5: 0 | I5: 5188810 | J5: 5188810 | K5: Matched | L5: Exact amount + date + transaction type | M5: 95 | N5: High | O5: No | P5: No duplicate candidate
A6: 1a018d91-db8a-416d-b49f-d03a84bc5c7b | B6: LED100005 | C6: 45145 | D6: 45145 | E6: 1000 | F6: 1000 | G6: 0 | H6: 0 | I6: ATM | J6: ATM WITHDRAWAL | K6: Matched | L6: Exact amount + date + transaction type | M6: 95 | N6: High | O6: No | P6: No duplicate candidate
A7: 33bd1687-6ab2-43c5-be5f-d150f412834c | B7: LED100006 | C7: 45160 | D7: 45160 | E7: 1 | F7: 1 | G7: 0 | H7: 0 | I7: UPI/3234 | J7: UPI PAYMENT/3234 | K7: Matched | L7: Exact amount + date + transaction type | M7: 95 | N7: High | O7: No | P7: No duplicate candidate
A8: b87c4941-ad5b-41b7-9cda-4956a05a042e | B8: LED100007 | C8: 45160 | D8: 45160 | E8: 3000 | F8: 3000 | G8: 0 | H8: 0 | I8: UPI/3234 | J8: UPI PAYMENT/3234 | K8: Matched | L8: Exact amount + date + transaction type | M8: 95 | N8: High | O8: No | P8: No duplicate candidate
A9: 8bba53c3-7a35-40d6-a38c-fc142c432455 | B9: LED100008 | C9: 45160 | D9: 45160 | E9: 300 | F9: 300 | G9: 0 | H9: 0 | I9: UPI/32345 | J9: UPI PAYMENT/32345 | K9: Matched | L9: Exact amount + date + transaction type | M9: 95 | N9: High | O9: No | P9: No duplicate candidate
A10: fd9c35d1-b32c-40f2-9e3e-0ddfe1d24cad | B10: LED100009 | C10: 45161 | D10: 45161 | E10: 1200 | F10: 1200 | G10: 0 | H10: 0 | I10: UPI/3235 | J10: UPI PAYMENT/3235 | K10: Matched | L10: Exact amount + date + transaction type | M10: 95 | N10: High | O10: No | P10: No duplicate candidate
A11: d2407a2c-15f3-46c2-b658-f9b66de3b6fd | B11: LED100010 | C11: 45161 | D11: 45161 | E11: 400 | F11: 400 | G11: 0 | H11: 0 | I11: UPI/ent | J11: UPI PAYMENT/ENT | K11: Matched | L11: Exact amount + date + transaction type | M11: 95 | N11: High | O11: No | P11: No duplicate candidate
A12: b347d492-3798-4af9-b684-b136ecc2163e | B12: LED100011 | C12: 45162 | D12: 45162 | E12: 500 | F12: 500 | G12: 0 | H12: 0 | I12: UPI/3236 | J12: UPI PAYMENT/3236 | K12: Matched | L12: Exact amount + date + transaction type | M12: 95 | N12: High | O12: No | P12: No duplicate candidate
A13: 2502b83f-52a0-459a-acc2-058856a6025f | B13: LED100012 | C13: 45162 | D13: 45162 | E13: 300 | F13: 300 | G13: 0 | H13: 0 | I13: UPI/3236 | J13: UPI PAYMENT/3236 | K13: Matched | L13: Exact amount + date + transaction type | M13: 95 | N13: High | O13: No | P13: No duplicate candidate
... A43: d2987357-92f2-4c9e-99a6-7692e931be22 | B43: LED100042 | C43: 45167 | D43: 45167 | E43: 600 | F43: 600 | G43: 0 | H43: 0 | I43: IMPS | J43: IMPS PAYMENT | K43: Matched | L43: Exact amount + date + transaction type | M43: 95 | N43: High | O43: No | P43: No duplicate candidate
A44: c2aa2280-77b1-4f14-a157-de477ec6b924 | C44: 45167 | E44: 100 | I44: UPI/3241 | K44: Unmatched Bank Transaction | L44: No suitable ledger transaction found | M44: 0 | N44: Low | O44: No | P44: No duplicate candidate
A45: ad797524-235c-4edb-b939-47647c17558c | B45: LED100044 | C45: 45168 | D45: 45168 | E45: 15 | F45: 15 | G45: 0 | H45: 0 | I45: UPI/JIOINAPPDIRECT/ | J45: UPI PAYMENT/JIOINAPPDIRECT/ | K45: Matched | L45: Exact amount + date + transaction type | M45: 95 | N45: High | O45: No | P45: No duplicate candidate
A46: 0494c9e3-ee71-4d31-b923-e723a1df44c3 | B46: LED100045 | C46: 45168 | D46: 45168 | E46: 600 | F46: 600 | G46: 0 | H46: 0 | I46: IMPS | J46: IMPS PAYMENT | K46: Matched | L46: Exact amount + date + transaction type | M46: 95 | N46: High | O46: No | P46: No duplicate candidate
A47: 3fd5bdaf-a0ec-4108-8f31-b39d54ba740d | B47: LED100046 | C47: 45168 | D47: 45168 | E47: 170 | F47: 170 | G47: 0 | H47: 0 | I47: IMPS | J47: IMPS PAYMENT | K47: Matched | L47: Exact amount + date + transaction type | M47: 95 | N47: High | O47: No | P47: No duplicate candidate
A48: 6ad58ee6-705a-4a71-8e43-c7ed1e88088f | B48: LED100047 | C48: 45169 | D48: 45169 | E48: 350 | F48: 350 | G48: 0 | H48: 0 | I48: NEFT | J48: NEFT PAYMENT | K48: Matched | L48: Exact reference + amount + date + type | M48: 100 | N48: High | O48: No | P48: No duplicate candidate
A49: c722d3c1-53df-4e6d-bc90-f14dbb97376b | B49: LED100048 | C49: 45169 | D49: 45169 | E49: 750 | F49: 750 | G49: 0 | H49: 0 | I49: IMPS | J49: IMPS PAYMENT | K49: Matched | L49: Exact amount + date + transaction type | M49: 95 | N49: High | O49: No | P49: No duplicate candidate
A50: c75c6d29-5934-42c3-bbda-dfc773f0100a | B50: LED100049 | C50: 45169 | D50: 45169 | E50: 1200 | F50: 1200 | G50: 0 | H50: 0 | I50: UPI/PAYTMNA | J50: UPI PAYMENT/PAYTMNA | K50: Matched | L50: Exact amount + date + transaction type | M50: 95 | N50: High | O50: No | P50: No duplicate candidate
A51: 794a682b-5b7a-4444-bd6a-5a3db9f9f1a3 | B51: LED100050 | C51: 45169 | D51: 45169 | E51: 200 | F51: 200 | G51: 0 | H51: 0 | I51: UPI/3609 | J51: UPI PAYMENT/3609 | K51: Matched | L51: Exact amount + date + transaction type | M51: 95 | N51: High | O51: No | P51: No duplicate candidate
A52: 7a6487f4-2008-4358-a761-2bd30994ae38 | B52: LED100051 | C52: 45169 | D52: 45169 | E52: 50 | F52: 50 | G52: 0 | H52: 0 | I52: UPI/3609 | J52: UPI PAYMENT/3609 | K52: Matched | L52: Exact amount + date + transaction type | M52: 95 | N52: High | O52: No | P52: No duplicate candidate
A53: 7a9c2faa-5032-42bb-9987-38cf36e1335b | B53: LED100052 | C53: 45170 | D53: 45170 | E53: 3500 | F53: 3500 | G53: 0 | H53: 0 | I53: UPI/32445 | J53: UPI PAYMENT/32445 | K53: Matched | L53: Exact amount + date + transaction type | M53: 95 | N53: High | O53: No | P53: No duplicate candidate
A54: 5ccc1be2-fbfb-4f60-9a87-17ee0b25c621 | B54: LED100053 | C54: 45172 | D54: 45172 | E54: 34 | F54: 34 | G54: 0 | H54: 0 | I54: UPI/3612 | J54: UPI PAYMENT/3612 | K54: Matched | L54: Exact amount + date + transaction type | M54: 95 | N54: High | O54: No | P54: No duplicate candidate
A55: 8a98421e-6026-4147-a99b-1335649ebb75 | B55: LED100054 | C55: 45173 | D55: 45173 | E55: 460 | F55: 460 | G55: 0 | H55: 0 | I55: UPI/32479 | J55: UPI PAYMENT/32479 | K55: Matched | L55: Exact amount + date + transaction type | M55: 95 | N55: High | O55: No | P55: No duplicate candidate
A56: b0bfec92-0fee-4c83-aa63-ec56255fa8ca | B56: LED100055 | C56: 45173 | D56: 45173 | E56: 200 | F56: 200 | G56: 0 | H56: 0 | I56: UPI/3613 | J56: UPI PAYMENT/3613 | K56: Matched | L56: Exact amount + date + transaction type | M56: 95 | N56: High | O56: No | P56: No duplicate candidate
... A158: 39cad768-4f42-4879-9fa4-12f7d5f75fea | B158: LED100157 | C158: 45205 | D158: 45205 | E158: 10 | F158: 10 | G158: 0 | H158: 0 | I158: UPI/36454 | J158: UPI PAYMENT/36454 | K158: Matched | L158: Exact amount + date + transaction type | M158: 95 | N158: High | O158: No | P158: No duplicate candidate
A159: 8af09e5a-a98a-4a0a-9648-64d457d85070 | C159: 45205 | E159: 700 | I159: UPI/3645 | K159: Unmatched Bank Transaction | L159: No suitable ledger transaction found | M159: 0 | N159: Low | O159: No | P159: No duplicate candidate
A160: 979fab68-939e-4b78-8f89-09c0dbb46472 | B160: LED100159 | C160: 45205 | D160: 45205 | E160: 220 | F160: 220 | G160: 0 | H160: 0 | I160: UPI/BHARATPE | J160: UPI PAYMENT/BHARATPE | K160: Matched | L160: Exact amount + date + transaction type | M160: 95 | N160: High | O160: No | P160: No duplicate candidate
A161: e30a976a-ef08-44a4-88c2-9105178a4999 | B161: LED100160 | C161: 45205 | D161: 45205 | E161: 220 | F161: 220 | G161: 0 | H161: 0 | I161: UPI/3279 | J161: UPI PAYMENT/3279 | K161: Matched | L161: Exact amount + date + transaction type | M161: 95 | N161: High | O161: No | P161: No duplicate candidate
A162: 9f694e56-84bb-4322-86d1-048ed5d7b7b0 | B162: LED100161 | C162: 45205 | D162: 45205 | E162: 30 | F162: 30 | G162: 0 | H162: 0 | I162: UPI/36458 | J162: UPI PAYMENT/36458 | K162: Matched | L162: Exact amount + date + transaction type | M162: 95 | N162: High | O162: No | P162: No duplicate candidate
A163: d59218dd-56a8-4c04-b1b4-ac13349f5d81 | B163: LED100162 | C163: 45206 | D163: 45206 | E163: 2330 | F163: 2330 | G163: 0 | H163: 0 | I163: NEFT | J163: NEFT PAYMENT | K163: Matched | L163: Exact reference + amount + date + type | M163: 100 | N163: High | O163: No | P163: No duplicate candidate
A164: 0cc87859-f3c0-4c5c-b51a-bfdd20a1433b | B164: LED100163 | C164: 45206 | D164: 45206 | E164: 19 | F164: 19 | G164: 0 | H164: 0 | I164: UPI/GPAYBILLREACHARGE | J164: UPI PAYMENT/GPAYBILLREACHARGE | K164: Matched | L164: Exact amount + date + transaction type | M164: 95 | N164: High | O164: No | P164: No duplicate candidate
A165: d8aaf10a-4bd0-4389-812e-1b1588d811a4 | B165: LED100164 | C165: 45206 | D165: 45206 | E165: 2000 | F165: 2000 | G165: 0 | H165: 0 | I165: UPI/BHARATPE | J165: UPI PAYMENT/BHARATPE | K165: Matched | L165: Exact amount + date + transaction type | M165: 95 | N165: High | O165: No | P165: No duplicate candidate
A166: 50052b56-dc7d-48e4-a9c6-3875ab1497d0 | B166: LED100165 | C166: 45206 | D166: 45206 | E166: 20 | F166: 20 | G166: 0 | H166: 0 | I166: UPI/36462 | J166: UPI PAYMENT/36462 | K166: Matched | L166: Exact amount + date + transaction type | M166: 95 | N166: High | O166: No | P166: No duplicate candidate
A167: 1bd129a3-31f0-4a9c-b646-532f3decb10a | B167: LED100166 | C167: 45206 | D167: 45206 | E167: 330 | F167: 330 | G167: 0 | H167: 0 | I167: UPI/32802 | J167: UPI PAYMENT/32802 | K167: Matched | L167: Exact amount + date + transaction type | M167: 95 | N167: High | O167: No | P167: No duplicate candidate
A168: 1ae3ff28-9cdb-461b-921e-5137cbb992b8 | B168: LED100167 | C168: 45207 | D168: 45207 | E168: 1900 | F168: 1900 | G168: 0 | H168: 0 | I168: UPI/3647 | J168: UPI PAYMENT/3647 | K168: Matched | L168: Exact amount + date + transaction type | M168: 95 | N168: High | O168: No | P168: No duplicate candidate
A169: 7c549684-4fc8-4b23-a781-d8f878d8ce29 | B169: LED100168 | C169: 45207 | D169: 45207 | E169: 100 | F169: 100 | G169: 0 | H169: 0 | I169: UPI/BHARATPE | J169: UPI PAYMENT/BHARATPE | K169: Matched | L169: Exact amount + date + transaction type | M169: 95 | N169: High | O169: No | P169: No duplicate candidate
A170: c59fa33b-8458-44ce-be05-d5944e2325c6 | B170: LED100169 | C170: 45208 | D170: 45208 | E170: 100 | F170: 100 | G170: 0 | H170: 0 | I170: NEFT | J170: NEFT PAYMENT | K170: Matched | L170: Exact reference + amount + date + type | M170: 100 | N170: High | O170: No | P170: No duplicate candidate
...

Sheet Executive Summary
B2: AUTOMATED BANK RECONCILIATION — MIS DASHBOARD | AA2: Row Labels | AB2: Count of match_status
B3: Reconciliation Monitoring & Exception Management | AA3: Amount Mismatch | AB3: 33
AA4: Duplicate Candidate | AB4: 7
B5: TOTAL BANK TRANSACTIONS | F5: TOTAL LEDGER TRANSACTIONS | J5: MATCHED TRANSACTIONS | AA5: Matched | AB5: 851
B6: {=COUNTA(_xlfn.UNIQUE(_xlfn._xlws.FILTER('Transaction Detail'!A2:A1000,'Transaction Detail'!A2:A1000<>"")))} -> 985 | F6: {=COUNTA(_xlfn.UNIQUE(_xlfn._xlws.FILTER('Transaction Detail'!B2:B1000,'Transaction Detail'!B2:B1000<>"")))} -> 985 | J6: =COUNTIF('Transaction Detail'!K2:K1000,"Matched") -> 851 | AA6: Potential Match | AB6: 65
AA7: Timing Difference | AB7: 28
AA8: Unmatched Bank Transaction | AB8: 8
B9: STRICT RECONCILIATION RATE | F9: EXCEPTION RECORDS | J9: CLASSIFIED / RESOLVED RATE | AA9: Unmatched Ledger Transaction | AB9: 1
B10: {=COUNTIF('Transaction Detail'!K2:K1000,"Matched")/COUNTA(_xlfn.UNIQUE(_xlfn._xlws.FILTER('Transaction Detail'!A2:A1000,'Transaction Detail'!A2:A1000<>"")))} -> 0.86395939 | F10: =COUNTA('Transaction Detail'!K2:K1000)-COUNTIF('Transaction Detail'!K2:K1000,"Matched") -> 142 | J10: =(COUNTIF('Transaction Detail'!K:K,"Matched")+COUNTIF('Transaction Detail'!K:K,"Potential Match")+COUNTIF('Transaction Detail'!K:K,"Timing Difference")+COUNTIF('Transaction Detail'!K:K,"Amount Mismatch"))/B6 -> 0.99187817 | AA10: Grand Total | AB10: 993

Sheet Exception Report
B2: AUTOMATED BANK RECONCILIATION — EXCEPTION REPORT
B3: Exception Monitoring & Transaction Investigation | AA3: Row Labels | AB3: Count of match_status
AA4: Amount Mismatch | AB4: 33
B5: TOTAL EXCEPTIONS | E5: AMOUNT MISMATCHES | H5: TIMING DIFFERENCES | K5: UNMATCHED TRANSACTIONS | AA5: Duplicate Candidate | AB5: 7
B6: =COUNTIF('Transaction Detail'!K:K,"Potential Match")+COUNTIF('Transaction Detail'!K:K,"Amount Mismatch")+COUNTIF('Transaction Detail'!K:K,"Timing Difference")+COUNTIF('Transaction Detail'!K:K,"Duplicate Candidate")+COUNTIF('Transaction Detail'!K:K,"Unmatched Bank Transaction")+COUNTIF('Transaction Detail'!K:K,"Unmatched Ledger Transaction") -> 142 | E6: =COUNTIF('Transaction Detail'!K:K,"Amount Mismatch") -> 33 | H6: =COUNTIF('Transaction Detail'!K:K,"Timing Difference") -> 28 | K6: =COUNTIF('Transaction Detail'!K:K,"Unmatched Bank Transaction")+COUNTIF('Transaction Detail'!K:K,"Unmatched Ledger Transaction") -> 9 | AA6: Potential Match | AB6: 65
AA7: Timing Difference | AB7: 28
AA8: Unmatched Bank Transaction | AB8: 8
AA9: Unmatched Ledger Transaction | AB9: 1
AA10: Grand Total | AB10: 142

Sheet Control Checks
XFD1: =LEFT(CELL("filename",A1),FIND("\dashboards\excel\",CELL("filename",A1))-1) -> #VALUE!
B2: AUTOMATED BANK RECONCILIATION — CONTROL CHECKS
B3: Data Quality, Reconciliation & Process Validation
B5: Control Check | C5: Expected | D5: Actual | E5: Status
B6: Bank Transactions | C6: 985 | D6: {=COUNTA(_xlfn.UNIQUE(_xlfn._xlws.FILTER('Transaction Detail'!A2:A10000,'Transaction Detail'!A2:A10000<>"")))} -> 985 | E6: =IF(C6=D6,"PASS","FAIL") -> PASS
B7: Ledger Transactions | C7: 985 | D7: {=COUNTA(_xlfn.UNIQUE(_xlfn._xlws.FILTER('Transaction Detail'!B2:B10000,'Transaction Detail'!B2:B10000<>"")))} -> 985 | E7: =IF(C7=D7,"PASS","FAIL") -> PASS
B8: Matched Transactions | C8: 851 | D8: =COUNTIF('Transaction Detail'!K:K,"Matched") -> 851 | E8: =IF(C8=D8,"PASS","FAIL") -> PASS
B9: Exception Records | C9: 142 | D9: =COUNTIFS('Transaction Detail'!K2:K10000,"<>Matched",'Transaction Detail'!K2:K10000,"<>") -> 142 | E9: =IF(C9=D9,"PASS","FAIL") -> PASS
B10: Reconciliation Output | C10: 993 | D10: =COUNTA('Transaction Detail'!A:A)-1 -> 993 | E10: =IF(C10=D10,"PASS","FAIL") -> PASS
B11: Status Classification | C11: 993 | D11: =COUNTA('Transaction Detail'!K:K)-1 -> 993 | E11: =IF(C11=D11,"PASS","FAIL") -> PASS
